<sdf version='1.6'>
  <world name='default'>
    <scene>
      <background>202 150 66 1</background>
      <ambient>0.4 0.4 0.4 1</ambient>
      <shadows>1</shadows>
    </scene>
    <physics name='default_physics' default='0' type='ode'>
      <max_step_size>0.0185</max_step_size>
      <real_time_factor>1</real_time_factor>
      <real_time_update_rate>1000</real_time_update_rate>
    </physics>
    <light name='directional_light_1' type='directional'>
      <pose frame=''>0 20 20 0.1 0.1 0</pose>
      <diffuse>1 1 1 1</diffuse>
      <specular>1 1 1 1</specular>
      <attenuation>
        <range>300</range>
      </attenuation>
      <direction>0.1 0.1 -1</direction>
      <cast_shadows>0</cast_shadows>
    </light>
    <light name='sun' type='directional'>
      <cast_shadows>1</cast_shadows>
      <pose frame=''>0 0 10 0 -0 0</pose>
      <diffuse>0.8 0.8 0.8 1</diffuse>
      <specular>0.2 0.2 0.2 1</specular>
      <attenuation>
        <range>1000</range>
        <constant>0.9</constant>
        <linear>0.01</linear>
        <quadratic>0.001</quadratic>
      </attenuation>
      <direction>-0.5 0.1 -0.9</direction>
    </light>
    <model name='curiosity_path'>
      <static>1</static>
      <link name='link'>
        <collision name='collision'>
          <geometry>
            <mesh>
              <uri>model://curiosity_path/meshes/curiosity_path25k.stl</uri>
              <scale>1 1 1</scale>
            </mesh>
          </geometry>
          <surface>
            <contact>
              <collide_bitmask>65535</collide_bitmask>
              <ode/>
            </contact>
            <friction>
              <ode>
                <mu>100</mu>
                <mu2>50</mu2>
              </ode>
              <torsional>
                <ode/>
              </torsional>
            </friction>
            <bounce/>
          </surface>
          <max_contacts>10</max_contacts>
        </collision>
        <visual name='visual'>
          <geometry>
            <mesh>
              <uri>model://curiosity_path/meshes/curiosity_path25k.dae</uri>
              <scale>1 1 1</scale>
            </mesh>
          </geometry>
        </visual>
        <self_collide>0</self_collide>
        <enable_wind>0</enable_wind>
        <kinematic>0</kinematic>
      </link>
      <pose frame=''>-136.5 127 14.21 0 -0 0</pose>
    </model>
    <model name='crater'>
      <static>1</static>
      <link name='link'>
        <inertial>
          <mass>0.25</mass>
          <inertia>
            <ixx>0.00015</ixx>
            <ixy>0</ixy>
            <ixz>0</ixz>
            <iyy>0.00015</iyy>
            <iyz>0</iyz>
            <izz>0.00015</izz>
          </inertia>
        </inertial>
        <collision name='collision'>
          <geometry>
            <mesh>
              <uri>model://crater/meshes/crater_martian_red.dae</uri>
              <scale>1 1 1</scale>
            </mesh>
          </geometry>
          <surface>
            <friction>
              <ode>
                <mu>30</mu>
                <mu2>30</mu2>
              </ode>
              <torsional>
                <ode/>
              </torsional>
            </friction>
            <contact>
              <ode>
                <kp>1e+06</kp>
                <kd>100</kd>
                <max_vel>1</max_vel>
                <min_depth>0.002</min_depth>
              </ode>
            </contact>
            <bounce/>
          </surface>
          <max_contacts>10</max_contacts>
        </collision>
        <visual name='visual'>
          <geometry>
            <mesh>
              <uri>model://crater/meshes/crater_martian_red.dae</uri>
              <scale>1 1 1</scale>
            </mesh>
          </geometry>
        </visual>
        <velocity_decay>
          <linear>0</linear>
          <angular>0</angular>
        </velocity_decay>
        <self_collide>0</self_collide>
        <kinematic>0</kinematic>
        <gravity>1</gravity>
        <enable_wind>0</enable_wind>
      </link>
      <pose frame=''>-48.502 1.5 -2.1 0 -0 0</pose>
    </model>
    <gravity>0 0 -3.711</gravity>
    <magnetic_field>6e-06 2.3e-05 -4.2e-05</magnetic_field>
    <atmosphere type='adiabatic'/>
    <wind/>
    <spherical_coordinates>
      <surface_model>EARTH_WGS84</surface_model>
      <latitude_deg>0</latitude_deg>
      <longitude_deg>0</longitude_deg>
      <elevation>0</elevation>
      <heading_deg>0</heading_deg>
    </spherical_coordinates>
    <model name='rover'>
      <link name='body'>
        <pose frame=''>0 0 0 0 -0 0</pose>
        <inertial>
          <pose frame=''>0 0 0 0 -0 0</pose>
          <mass>2.90211</mass>
          <inertia>
            <ixx>0.0449849</ixx>
            <ixy>0.00479069</ixy>
            <ixz>0.00169664</ixz>
            <iyy>0.0360955</iyy>
            <iyz>0.00496816</iyz>
            <izz>0.0468327</izz>
          </inertia>
        </inertial>
        <collision name='body_collision_collision'>
          <pose frame=''>0.06131 0.25841 -0.36404 1.57079 -0.0741 -0</pose>
          <geometry>
            <mesh>
              <scale>1 1 1</scale>
              <uri>/home/ashwin/rover_ws/src/2020_rover/rover_sim/models/rover/meshes/body.STL</uri>
            </mesh>
          </geometry>
          <surface>
            <contact>
              <ode/>
            </contact>
            <friction>
              <ode/>
              <torsional>
                <ode/>
              </torsional>
            </friction>
            <bounce/>
          </surface>
          <max_contacts>10</max_contacts>
        </collision>
        <collision name='body_fixed_joint_lump__camera_link_collision_1'>
          <pose frame=''>-0.09 -1.6e-05 0 0 -0 -0.003185</pose>
          <geometry>
            <box>
              <size>0.01 0.01 0.01</size>
            </box>
          </geometry>
          <surface>
            <contact>
              <ode/>
            </contact>
            <friction>
              <ode/>
              <torsional>
                <ode/>
              </torsional>
            </friction>
            <bounce/>
          </surface>
          <max_contacts>10</max_contacts>
        </collision>
        <collision name='body_fixed_joint_lump__depthcamera_link_collision_2'>
          <pose frame=''>-0.09 -1.6e-05 0 0 -0 3.14</pose>
          <geometry>
            <box>
              <size>0.01 0.01 0.01</size>
            </box>
          </geometry>
          <surface>
            <contact>
              <ode/>
            </contact>
            <friction>
              <ode/>
              <torsional>
                <ode/>
              </torsional>
            </friction>
            <bounce/>
          </surface>
          <max_contacts>10</max_contacts>
        </collision>
        <visual name='body_visual_visual'>
          <pose frame=''>0.06131 0.25841 -0.36404 1.57079 -0.0741 -0</pose>
          <geometry>
            <mesh>
              <scale>1 1 1</scale>
              <uri>/home/ashwin/rover_ws/src/2020_rover/rover_sim/models/rover/meshes/body.dae</uri>
            </mesh>
          </geometry>
          <material>
            <script>
              <uri>__default__</uri>
              <name>__default__</name>
            </script>
          </material>
        </visual>
        <velocity_decay/>
        <sensor name='body_contact_sensor' type='contact'>
          <update_rate>30</update_rate>
          <always_on>1</always_on>
          <contact>
            <collision>body_collision_collision</collision>
            <topic>rover/bumper_contact</topic>
          </contact>
          <plugin name='gazebo_ros_bumper_controller' filename='libgazebo_ros_bumper.so'>
            <alwaysOn>1</alwaysOn>
            <updateRate>3.0</updateRate>
            <bumperTopicName>rover/robot_bumper</bumperTopicName>
            <frameName>body</frameName>
            <robotNamespace>/</robotNamespace>
          </plugin>
        </sensor>
        <velocity_decay/>
        <sensor name='camera1' type='camera'>
          <update_rate>30</update_rate>
          <camera name='head'>
            <horizontal_fov>1.3</horizontal_fov>
            <image>
              <width>360</width>
              <height>240</height>
              <format>R8G8B8</format>
            </image>
            <clip>
              <near>0.02</near>
              <far>300</far>
            </clip>
            <noise>
              <type>gaussian</type>
              <mean>0</mean>
              <stddev>0.007</stddev>
            </noise>
          </camera>
          <plugin name='camera_controller' filename='libgazebo_ros_camera.so'>
            <alwaysOn>1</alwaysOn>
            <updateRate>0.0</updateRate>
            <cameraName>rover/camera</cameraName>
            <imageTopicName>image_raw</imageTopicName>
            <cameraInfoTopicName>camera_info</cameraInfoTopicName>
            <frameName>camera_link</frameName>
            <hackBaseline>0.07</hackBaseline>
            <distortionK1>0.0</distortionK1>
            <distortionK2>0.0</distortionK2>
            <distortionK3>0.0</distortionK3>
            <distortionT1>0.0</distortionT1>
            <distortionT2>0.0</distortionT2>
            <robotNamespace>/</robotNamespace>
          </plugin>
          <pose frame=''>-0.1 0 0 0 -0 3.14</pose>
        </sensor>
        <velocity_decay/>
        <sensor name='depthcamera' type='depth'>
          <update_rate>10</update_rate>
          <camera name='__default__'>
            <horizontal_fov>1.0472</horizontal_fov>
            <image>
              <width>640</width>
              <height>480</height>
              <format>R8G8B8</format>
            </image>
            <clip>
              <near>0.05</near>
              <far>3</far>
            </clip>
          </camera>
          <plugin name='depthcamera_controller' filename='libgazebo_ros_openni_kinect.so'>
            <baseline>0.2</baseline>
            <alwaysOn>1</alwaysOn>
            <updateRate>1.0</updateRate>
            <cameraName>rover/depthcamera</cameraName>
            <imageTopicName>depthcamera/depth/image_raw</imageTopicName>
            <cameraInfoTopicName>depthcamera/depth/camera_info</cameraInfoTopicName>
            <depthImageTopicName>depthcamera/depth/image_raw</depthImageTopicName>
            <depthImageInfoTopicName>depthcamera/depth/camera_info</depthImageInfoTopicName>
            <pointCloudTopicName>depthcamera/depth/points</pointCloudTopicName>
            <frameName>pointcloud_link</frameName>
            <pointCloudCutoff>0.5</pointCloudCutoff>
            <pointCloudCutoffMax>3.0</pointCloudCutoffMax>
            <distortionK1>0.00000001</distortionK1>
            <distortionK2>0.00000001</distortionK2>
            <distortionK3>0.00000001</distortionK3>
            <distortionT1>0.00000001</distortionT1>
            <distortionT2>0.00000001</distortionT2>
            <CxPrime>0</CxPrime>
            <Cx>0</Cx>
            <Cy>0</Cy>
            <focalLength>0</focalLength>
            <hackBaseline>0</hackBaseline>
            <robotNamespace>/</robotNamespace>
          </plugin>
          <pose frame=''>-0.1 0 0 0 -0 3.14</pose>
        </sensor>
        <velocity_decay/>
        <sensor name='imu' type='imu'>
          <always_on>1</always_on>
          <pose frame=''>-0.032 0 0.068 0 -0 3.14</pose>
          <imu/>
        </sensor>
        <gravity>1</gravity>
        <velocity_decay/>
        <sensor name='lds_lfcd_sensor' type='ray'>
          <visualize>0</visualize>
          <update_rate>5</update_rate>
          <ray>
            <scan>
              <horizontal>
                <samples>360</samples>
                <resolution>1</resolution>
                <min_angle>-90</min_angle>
                <max_angle>90</max_angle>
              </horizontal>
              <vertical>
                <samples>1</samples>
                <min_angle>0</min_angle>
                <max_angle>0</max_angle>
              </vertical>
            </scan>
            <range>
              <min>0.45</min>
              <max>4.5</max>
              <resolution>0.015</resolution>
            </range>
            <noise>
              <type>gaussian</type>
              <mean>0</mean>
              <stddev>0.01</stddev>
            </noise>
          </ray>
          <plugin name='gazebo_ros_lds_lfcd_controller' filename='libgazebo_ros_laser.so'>
            <topicName>rover/scan</topicName>
            <frameName>base_scan</frameName>
            <robotNamespace>/</robotNamespace>
          </plugin>
          <pose frame=''>-0.075 0.03 -0.075 0 -0.275 0</pose>
        </sensor>
        <self_collide>0</self_collide>
        <enable_wind>0</enable_wind>
        <kinematic>0</kinematic>
      </link>
      <link name='rocker_left'>
        <pose frame=''>0 -0.16496 -0.30899 1.49669 -0 1.57079</pose>
        <inertial>
          <pose frame=''>0 0 0 0 -0 0</pose>
          <mass>0.537822</mass>
          <inertia>
            <ixx>0.000926946</ixx>
            <ixy>0.000154689</ixy>
            <ixz>1.88013e-05</ixz>
            <iyy>0.0101156</iyy>
            <iyz>5.30969e-06</iyz>
            <izz>0.0107754</izz>
          </inertia>
        </inertial>
        <collision name='rocker_left_collision_collision'>
          <pose frame=''>0.42337 -0.05944 0.05707 3.14159 -1.57079 -3.13761</pose>
          <geometry>
            <mesh>
              <scale>1 1 1</scale>
              <uri>/home/ashwin/rover_ws/src/2020_rover/rover_sim/models/rover/meshes/rocker_left.STL</uri>
            </mesh>
          </geometry>
          <surface>
            <contact>
              <ode/>
            </contact>
            <friction>
              <ode/>
              <torsional>
                <ode/>
              </torsional>
            </friction>
            <bounce/>
          </surface>
          <max_contacts>10</max_contacts>
        </collision>
        <visual name='rocker_left_visual_visual'>
          <pose frame=''>0.42337 -0.05944 0.05707 3.14159 -1.57079 -3.13761</pose>
          <geometry>
            <mesh>
              <scale>1 1 1</scale>
              <uri>/home/ashwin/rover_ws/src/2020_rover/rover_sim/models/rover/meshes/rocker_left.dae</uri>
            </mesh>
          </geometry>
          <material>
            <script>
              <uri>__default__</uri>
              <name>__default__</name>
            </script>
          </material>
        </visual>
        <gravity>1</gravity>
        <velocity_decay/>
        <sensor name='rocker_left_contact_sensor' type='contact'>
          <update_rate>30</update_rate>
          <always_on>1</always_on>
          <contact>
            <collision>rocker_left_collision_collision</collision>
            <topic>rover/bumper_contact</topic>
          </contact>
          <plugin name='gazebo_ros_bumper_controller' filename='libgazebo_ros_bumper.so'>
            <alwaysOn>1</alwaysOn>
            <updateRate>3.0</updateRate>
            <bumperTopicName>rover/robot_bumper</bumperTopicName>
            <frameName>rocker_left</frameName>
            <robotNamespace>/</robotNamespace>
          </plugin>
        </sensor>
        <self_collide>0</self_collide>
        <enable_wind>0</enable_wind>
        <kinematic>0</kinematic>
      </link>
      <joint name='body_rocker_left' type='revolute'>
        <child>rocker_left</child>
        <parent>body</parent>
        <axis>
          <xyz>-0.074039 0 0.997255</xyz>
          <limit>
            <lower>-1e+16</lower>
            <upper>1e+16</upper>
          </limit>
          <dynamics>
            <spring_reference>0</spring_reference>
            <spring_stiffness>0</spring_stiffness>
          </dynamics>
          <use_parent_model_frame>1</use_parent_model_frame>
        </axis>
      </joint>
      <link name='bogie_left'>
        <pose frame=''>-0.188573 -0.172819 -0.408455 1.57478 -0.074106 -1.3e-05</pose>
        <inertial>
          <pose frame=''>0 0 0 0 -0 0</pose>
          <mass>0.62126</mass>
          <inertia>
            <ixx>0.00448583</ixx>
            <ixy>0.00477854</ixy>
            <ixz>0.00060706</ixz>
            <iyy>0.00810725</iyy>
            <iyz>0.000593846</iyz>
            <izz>0.0118999</izz>
          </inertia>
        </inertial>
        <collision name='bogie_left_collision_collision'>
          <pose frame=''>0.25249 0.02578 -0.43123 0 -0 0</pose>
          <geometry>
            <mesh>
              <scale>1 1 1</scale>
              <uri>/home/ashwin/rover_ws/src/2020_rover/rover_sim/models/rover/meshes/bogie_left.STL</uri>
            </mesh>
          </geometry>
          <surface>
            <contact>
              <ode/>
            </contact>
            <friction>
              <ode/>
              <torsional>
                <ode/>
              </torsional>
            </friction>
            <bounce/>
          </surface>
          <max_contacts>10</max_contacts>
        </collision>
        <visual name='bogie_left_visual_visual'>
          <pose frame=''>0.25249 0.02578 -0.43123 0 -0 0</pose>
          <geometry>
            <mesh>
              <scale>1 1 1</scale>
              <uri>/home/ashwin/rover_ws/src/2020_rover/rover_sim/models/rover/meshes/bogie_left.dae</uri>
            </mesh>
          </geometry>
          <material>
            <script>
              <uri>__default__</uri>
              <name>__default__</name>
            </script>
          </material>
        </visual>
        <velocity_decay/>
        <sensor name='bogie_left_contact_sensor' type='contact'>
          <update_rate>30</update_rate>
          <always_on>1</always_on>
          <contact>
            <collision>bogie_left_collision_collision</collision>
            <topic>rover/bumper_contact</topic>
          </contact>
          <plugin name='gazebo_ros_bumper_controller' filename='libgazebo_ros_bumper.so'>
            <alwaysOn>1</alwaysOn>
            <updateRate>3.0</updateRate>
            <bumperTopicName>rover/robot_bumper</bumperTopicName>
            <frameName>bogie_left</frameName>
            <robotNamespace>/</robotNamespace>
          </plugin>
        </sensor>
        <gravity>1</gravity>
        <velocity_decay/>
        <sensor name='imu' type='imu'>
          <always_on>1</always_on>
          <pose frame=''>0.105 -0.179 0.078 -1.58 0 0</pose>
          <imu/>
        </sensor>
        <self_collide>0</self_collide>
        <enable_wind>0</enable_wind>
        <kinematic>0</kinematic>
      </link>
      <joint name='rocker_left_bogie_left' type='revolute'>
        <child>bogie_left</child>
        <parent>rocker_left</parent>
        <axis>
          <xyz>0.000282 -0.999992 -0.00397</xyz>
          <limit>
            <lower>-1e+16</lower>
            <upper>1e+16</upper>
          </limit>
          <dynamics>
            <spring_reference>0</spring_reference>
            <spring_stiffness>0</spring_stiffness>
          </dynamics>
          <use_parent_model_frame>1</use_parent_model_frame>
        </axis>
      </joint>
      <link name='corner_lf'>
        <pose frame=''>-0.3758 -0.164771 -0.504318 1.57478 -0.074106 -1.3e-05</pose>
        <inertial>
          <pose frame=''>0 0 0 0 -0 0</pose>
          <mass>0.304193</mass>
          <inertia>
            <ixx>0.00138425</ixx>
            <ixy>7.62005e-05</ixy>
            <ixz>8.45009e-06</ixz>
            <iyy>0.00036423</iyy>
            <iyz>0.000114298</iyz>
            <izz>0.00113642</izz>
          </inertia>
        </inertial>
        <collision name='corner_lf_collision_collision'>
          <pose frame=''>0.44631 0.10755 -0.42351 0 -0 0</pose>
          <geometry>
            <mesh>
              <scale>1 1 1</scale>
              <uri>/home/ashwin/rover_ws/src/2020_rover/rover_sim/models/rover/meshes/corner_lf.STL</uri>
            </mesh>
          </geometry>
          <surface>
            <contact>
              <ode/>
            </contact>
            <friction>
              <ode/>
              <torsional>
                <ode/>
              </torsional>
            </friction>
            <bounce/>
          </surface>
          <max_contacts>10</max_contacts>
        </collision>
        <visual name='corner_lf_visual_visual'>
          <pose frame=''>0.44631 0.10755 -0.42351 0 -0 0</pose>
          <geometry>
            <mesh>
              <scale>1 1 1</scale>
              <uri>/home/ashwin/rover_ws/src/2020_rover/rover_sim/models/rover/meshes/corner_lf.dae</uri>
            </mesh>
          </geometry>
          <material>
            <script>
              <uri>__default__</uri>
              <name>__default__</name>
            </script>
          </material>
        </visual>
        <velocity_decay/>
        <sensor name='corner_lf_contact_sensor' type='contact'>
          <update_rate>30</update_rate>
          <always_on>1</always_on>
          <contact>
            <collision>corner_lf_collision_collision</collision>
            <topic>rover/bumper_contact</topic>
          </contact>
          <plugin name='gazebo_ros_bumper_controller' filename='libgazebo_ros_bumper.so'>
            <alwaysOn>1</alwaysOn>
            <updateRate>3.0</updateRate>
            <bumperTopicName>rover/robot_bumper</bumperTopicName>
            <frameName>corner_lf</frameName>
            <robotNamespace>/</robotNamespace>
          </plugin>
        </sensor>
        <gravity>1</gravity>
        <velocity_decay/>
        <sensor name='imu' type='imu'>
          <always_on>1</always_on>
          <pose frame=''>0.028 -0.089 0.01 -1.58 0 0</pose>
          <imu/>
        </sensor>
        <self_collide>0</self_collide>
        <enable_wind>0</enable_wind>
        <kinematic>0</kinematic>
      </link>
      <joint name='bogie_left_corner_lf' type='revolute'>
        <child>corner_lf</child>
        <parent>bogie_left</parent>
        <axis>
          <xyz>8e-06 0.00397 -0.999986</xyz>
          <limit>
            <lower>-1e+16</lower>
            <upper>1e+16</upper>
          </limit>
          <dynamics>
            <spring_reference>0</spring_reference>
            <spring_stiffness>0</spring_stiffness>
          </dynamics>
          <use_parent_model_frame>1</use_parent_model_frame>
        </axis>
      </joint>
      <link name='wheel_lf'>
        <pose frame=''>-0.341332 -0.174465 -0.591475 1.57478 -0.074106 -1.3e-05</pose>
        <inertial>
          <pose frame=''>0 0 0 0 -0 0</pose>
          <mass>1.36815</mass>
          <inertia>
            <ixx>0.00366758</ixx>
            <ixy>5.8572e-08</ixy>
            <ixz>2.50672e-08</ixz>
            <iyy>0.00366756</iyy>
            <iyz>1.97672e-08</iyz>
            <izz>0.00544769</izz>
          </inertia>
        </inertial>
        <collision name='wheel_lf_collision_collision'>
          <pose frame=''>0.41838 0.19698 -0.43356 0 -0 0</pose>
          <geometry>
            <mesh>
              <scale>1 1 1</scale>
              <uri>/home/ashwin/rover_ws/src/2020_rover/rover_sim/models/rover/meshes/wheel_lf.STL</uri>
            </mesh>
          </geometry>
          <max_contacts>10</max_contacts>
          <surface>
            <contact>
              <ode/>
            </contact>
            <bounce/>
            <friction>
              <torsional>
                <ode/>
              </torsional>
              <ode/>
            </friction>
          </surface>
        </collision>
        <visual name='wheel_lf_visual_visual'>
          <pose frame=''>0.41838 0.19698 -0.43356 0 -0 0</pose>
          <geometry>
            <mesh>
              <scale>1 1 1</scale>
              <uri>/home/ashwin/rover_ws/src/2020_rover/rover_sim/models/rover/meshes/wheel_lf.dae</uri>
            </mesh>
          </geometry>
        </visual>
        <self_collide>0</self_collide>
        <enable_wind>0</enable_wind>
        <kinematic>0</kinematic>
      </link>
      <joint name='corner_lf_wheel_lf' type='revolute'>
        <child>wheel_lf</child>
        <parent>corner_lf</parent>
        <axis>
          <xyz>0.000282 -0.999992 -0.00397</xyz>
          <limit>
            <lower>-1e+16</lower>
            <upper>1e+16</upper>
          </limit>
          <dynamics>
            <spring_reference>0</spring_reference>
            <spring_stiffness>0</spring_stiffness>
          </dynamics>
          <use_parent_model_frame>1</use_parent_model_frame>
        </axis>
      </joint>
      <link name='wheel_lm'>
        <pose frame=''>-0.071069 -0.250377 -0.579615 1.57478 -0.074106 -1.3e-05</pose>
        <inertial>
          <pose frame=''>0 0 0 0 -0 0</pose>
          <mass>1.36814</mass>
          <inertia>
            <ixx>0.0036676</ixx>
            <ixy>4.81811e-08</ixy>
            <ixz>1.99016e-08</ixz>
            <iyy>0.00366753</iyy>
            <iyz>2.50805e-08</iyz>
            <izz>0.00544769</izz>
          </inertia>
        </inertial>
        <collision name='wheel_lm_collision_collision'>
          <pose frame=''>0.14798 0.20486 -0.50951 0 -0 0</pose>
          <geometry>
            <mesh>
              <scale>1 1 1</scale>
              <uri>/home/ashwin/rover_ws/src/2020_rover/rover_sim/models/rover/meshes/wheel_lm.STL</uri>
            </mesh>
          </geometry>
          <max_contacts>10</max_contacts>
          <surface>
            <contact>
              <ode/>
            </contact>
            <bounce/>
            <friction>
              <torsional>
                <ode/>
              </torsional>
              <ode/>
            </friction>
          </surface>
        </collision>
        <visual name='wheel_lm_visual_visual'>
          <pose frame=''>0.14798 0.20486 -0.50951 0 -0 0</pose>
          <geometry>
            <mesh>
              <scale>1 1 1</scale>
              <uri>/home/ashwin/rover_ws/src/2020_rover/rover_sim/models/rover/meshes/wheel_lm.dae</uri>
            </mesh>
          </geometry>
        </visual>
        <self_collide>0</self_collide>
        <enable_wind>0</enable_wind>
        <kinematic>0</kinematic>
      </link>
      <joint name='bogie_left_wheel_lm' type='revolute'>
        <child>wheel_lm</child>
        <parent>bogie_left</parent>
        <axis>
          <xyz>0.000282 -0.999992 -0.00397</xyz>
          <limit>
            <lower>-1e+16</lower>
            <upper>1e+16</upper>
          </limit>
          <dynamics>
            <spring_reference>0</spring_reference>
            <spring_stiffness>0</spring_stiffness>
          </dynamics>
          <use_parent_model_frame>1</use_parent_model_frame>
        </axis>
      </joint>
      <link name='corner_lb'>
        <pose frame=''>0.183668 -0.165091 -0.466394 1.57478 -0.074106 -1.3e-05</pose>
        <inertial>
          <pose frame=''>0 0 0 0 -0 0</pose>
          <mass>0.304193</mass>
          <inertia>
            <ixx>0.00137498</ixx>
            <ixy>0.000122975</ixy>
            <ixz>1.73924e-05</ixz>
            <iyy>0.000373445</iyy>
            <iyz>0.000113334</iyz>
            <izz>0.00113648</izz>
          </inertia>
        </inertial>
        <collision name='corner_lb_collision_collision'>
          <pose frame=''>-0.11444 0.11112 -0.42351 0 -0 0</pose>
          <geometry>
            <mesh>
              <scale>1 1 1</scale>
              <uri>/home/ashwin/rover_ws/src/2020_rover/rover_sim/models/rover/meshes/corner_lb.STL</uri>
            </mesh>
          </geometry>
          <surface>
            <contact>
              <ode/>
            </contact>
            <friction>
              <ode/>
              <torsional>
                <ode/>
              </torsional>
            </friction>
            <bounce/>
          </surface>
          <max_contacts>10</max_contacts>
        </collision>
        <visual name='corner_lb_visual_visual'>
          <pose frame=''>-0.11444 0.11112 -0.42351 0 -0 0</pose>
          <geometry>
            <mesh>
              <scale>1 1 1</scale>
              <uri>/home/ashwin/rover_ws/src/2020_rover/rover_sim/models/rover/meshes/corner_lb.dae</uri>
            </mesh>
          </geometry>
          <material>
            <script>
              <uri>__default__</uri>
              <name>__default__</name>
            </script>
          </material>
        </visual>
        <velocity_decay/>
        <sensor name='corner_lb_contact_sensor' type='contact'>
          <update_rate>30</update_rate>
          <always_on>1</always_on>
          <contact>
            <collision>corner_lb_collision_collision</collision>
            <topic>rover/bumper_contact</topic>
          </contact>
          <plugin name='gazebo_ros_bumper_controller' filename='libgazebo_ros_bumper.so'>
            <alwaysOn>1</alwaysOn>
            <updateRate>3.0</updateRate>
            <bumperTopicName>rover/robot_bumper</bumperTopicName>
            <frameName>corner_lb</frameName>
            <robotNamespace>/</robotNamespace>
          </plugin>
        </sensor>
        <gravity>1</gravity>
        <velocity_decay/>
        <sensor name='imu' type='imu'>
          <always_on>1</always_on>
          <pose frame=''>0.04 -0.069 0.005 -1.58 0 0</pose>
          <imu/>
        </sensor>
        <self_collide>0</self_collide>
        <enable_wind>0</enable_wind>
        <kinematic>0</kinematic>
      </link>
      <joint name='rocker_left_corner_lb' type='revolute'>
        <child>corner_lb</child>
        <parent>rocker_left</parent>
        <axis>
          <xyz>-0.044518 0.003953 -0.999</xyz>
          <limit>
            <lower>-1e+16</lower>
            <upper>1e+16</upper>
          </limit>
          <dynamics>
            <spring_reference>0</spring_reference>
            <spring_stiffness>0</spring_stiffness>
          </dynamics>
          <use_parent_model_frame>1</use_parent_model_frame>
        </axis>
      </joint>
      <link name='wheel_lb'>
        <pose frame=''>0.229013 -0.169788 -0.531905 1.57478 -0.074106 -1.3e-05</pose>
        <inertial>
          <pose frame=''>0 0 0 0 -0 0</pose>
          <mass>1.36815</mass>
          <inertia>
            <ixx>0.00366794</ixx>
            <ixy>1.26412e-08</ixy>
            <ixz>2.71593e-05</ixz>
            <iyy>0.00366762</iyy>
            <iyz>3.23854e-06</iyz>
            <izz>0.00544727</izz>
          </inertia>
        </inertial>
        <collision name='wheel_lb_collision_collision'>
          <pose frame=''>-0.15482 0.17979 -0.42848 0 -0 0</pose>
          <geometry>
            <mesh>
              <scale>1 1 1</scale>
              <uri>/home/ashwin/rover_ws/src/2020_rover/rover_sim/models/rover/meshes/wheel_lb.STL</uri>
            </mesh>
          </geometry>
          <max_contacts>10</max_contacts>
          <surface>
            <contact>
              <ode/>
            </contact>
            <bounce/>
            <friction>
              <torsional>
                <ode/>
              </torsional>
              <ode/>
            </friction>
          </surface>
        </collision>
        <visual name='wheel_lb_visual_visual'>
          <pose frame=''>-0.15482 0.17979 -0.42848 0 -0 0</pose>
          <geometry>
            <mesh>
              <scale>1 1 1</scale>
              <uri>/home/ashwin/rover_ws/src/2020_rover/rover_sim/models/rover/meshes/wheel_lb.dae</uri>
            </mesh>
          </geometry>
        </visual>
        <self_collide>0</self_collide>
        <enable_wind>0</enable_wind>
        <kinematic>0</kinematic>
      </link>
      <joint name='corner_lb_wheel_lb' type='revolute'>
        <child>wheel_lb</child>
        <parent>corner_lb</parent>
        <axis>
          <xyz>0.015614 -0.999865 -0.004646</xyz>
          <limit>
            <lower>-1e+16</lower>
            <upper>1e+16</upper>
          </limit>
          <dynamics>
            <spring_reference>0</spring_reference>
            <spring_stiffness>0</spring_stiffness>
          </dynamics>
          <use_parent_model_frame>1</use_parent_model_frame>
        </axis>
      </joint>
      <link name='rocker_right'>
        <pose frame=''>0 0.1649 -0.30899 1.57079 -0.0741 -0</pose>
        <inertial>
          <pose frame=''>0 0 0 0 -0 0</pose>
          <mass>0.526239</mass>
          <inertia>
            <ixx>0.000919589</ixx>
            <ixy>0.000157243</ixy>
            <ixz>1.51548e-05</ixz>
            <iyy>0.00982888</iyy>
            <iyz>5.68327e-06</iyz>
            <izz>0.0104855</izz>
          </inertia>
        </inertial>
        <collision name='rocker_right_collision_collision'>
          <pose frame=''>0.05707 -0.05944 -0.0935 0 -0 0</pose>
          <geometry>
            <mesh>
              <scale>1 1 1</scale>
              <uri>/home/ashwin/rover_ws/src/2020_rover/rover_sim/models/rover/meshes/rocker_right.STL</uri>
            </mesh>
          </geometry>
          <surface>
            <contact>
              <ode/>
            </contact>
            <friction>
              <ode/>
              <torsional>
                <ode/>
              </torsional>
            </friction>
            <bounce/>
          </surface>
          <max_contacts>10</max_contacts>
        </collision>
        <visual name='rocker_right_visual_visual'>
          <pose frame=''>0.05707 -0.05944 -0.0935 0 -0 0</pose>
          <geometry>
            <mesh>
              <scale>1 1 1</scale>
              <uri>/home/ashwin/rover_ws/src/2020_rover/rover_sim/models/rover/meshes/rocker_right.dae</uri>
            </mesh>
          </geometry>
          <material>
            <script>
              <uri>__default__</uri>
              <name>__default__</name>
            </script>
          </material>
        </visual>
        <gravity>1</gravity>
        <velocity_decay/>
        <sensor name='rocker_right_contact_sensor' type='contact'>
          <update_rate>30</update_rate>
          <always_on>1</always_on>
          <contact>
            <collision>rocker_right_collision_collision</collision>
            <topic>rover/bumper_contact</topic>
          </contact>
          <plugin name='gazebo_ros_bumper_controller' filename='libgazebo_ros_bumper.so'>
            <alwaysOn>1</alwaysOn>
            <updateRate>3.0</updateRate>
            <bumperTopicName>rover/robot_bumper</bumperTopicName>
            <frameName>rocker_right</frameName>
            <robotNamespace>/</robotNamespace>
          </plugin>
        </sensor>
        <self_collide>0</self_collide>
        <enable_wind>0</enable_wind>
        <kinematic>0</kinematic>
      </link>
      <joint name='body_rocker_right' type='revolute'>
        <child>rocker_right</child>
        <parent>body</parent>
        <axis>
          <xyz>0 1 -6e-06</xyz>
          <limit>
            <lower>-1e+16</lower>
            <upper>1e+16</upper>
          </limit>
          <dynamics>
            <spring_reference>0</spring_reference>
            <spring_stiffness>0</spring_stiffness>
          </dynamics>
          <use_parent_model_frame>1</use_parent_model_frame>
        </axis>
      </joint>
      <link name='bogie_right'>
        <pose frame=''>-0.188574 0.172999 -0.408454 1.57079 -0.0741 -0</pose>
        <inertial>
          <pose frame=''>0 0 0 0 -0 0</pose>
          <mass>0.62126</mass>
          <inertia>
            <ixx>0.00453008</ixx>
            <ixy>0.0049035</ixy>
            <ixz>0.000635834</ixz>
            <iyy>0.00836086</iyy>
            <iyz>0.000607789</iyz>
            <izz>0.0121913</izz>
          </inertia>
        </inertial>
        <collision name='bogie_right_collision_collision'>
          <pose frame=''>0.25249 0.02578 -0.0854 0 -0 0</pose>
          <geometry>
            <mesh>
              <scale>1 1 1</scale>
              <uri>/home/ashwin/rover_ws/src/2020_rover/rover_sim/models/rover/meshes/bogie_right.STL</uri>
            </mesh>
          </geometry>
          <surface>
            <contact>
              <ode/>
            </contact>
            <friction>
              <ode/>
              <torsional>
                <ode/>
              </torsional>
            </friction>
            <bounce/>
          </surface>
          <max_contacts>10</max_contacts>
        </collision>
        <visual name='bogie_right_visual_visual'>
          <pose frame=''>0.25249 0.02578 -0.0854 0 -0 0</pose>
          <geometry>
            <mesh>
              <scale>1 1 1</scale>
              <uri>/home/ashwin/rover_ws/src/2020_rover/rover_sim/models/rover/meshes/bogie_right.dae</uri>
            </mesh>
          </geometry>
          <material>
            <script>
              <uri>__default__</uri>
              <name>__default__</name>
            </script>
          </material>
        </visual>
        <velocity_decay/>
        <sensor name='bogie_right_contact_sensor' type='contact'>
          <update_rate>30</update_rate>
          <always_on>1</always_on>
          <contact>
            <collision>bogie_right_collision_collision</collision>
            <topic>rover/bumper_contact</topic>
          </contact>
          <plugin name='gazebo_ros_bumper_controller' filename='libgazebo_ros_bumper.so'>
            <alwaysOn>1</alwaysOn>
            <updateRate>3.0</updateRate>
            <bumperTopicName>rover/robot_bumper</bumperTopicName>
            <frameName>bogie_right</frameName>
            <robotNamespace>/</robotNamespace>
          </plugin>
        </sensor>
        <gravity>1</gravity>
        <velocity_decay/>
        <sensor name='imu' type='imu'>
          <always_on>1</always_on>
          <pose frame=''>0.066 -0.182 -0.079 -1.58 0 0</pose>
          <imu/>
        </sensor>
        <self_collide>0</self_collide>
        <enable_wind>0</enable_wind>
        <kinematic>0</kinematic>
      </link>
      <joint name='rocker_right_bogie_right' type='revolute'>
        <child>bogie_right</child>
        <parent>rocker_right</parent>
        <axis>
          <xyz>-0 -1 6e-06</xyz>
          <limit>
            <lower>-1e+16</lower>
            <upper>1e+16</upper>
          </limit>
          <dynamics>
            <spring_reference>0</spring_reference>
            <spring_stiffness>0</spring_stiffness>
          </dynamics>
          <use_parent_model_frame>1</use_parent_model_frame>
        </axis>
      </joint>
      <link name='corner_rf'>
        <pose frame=''>-0.375799 0.165089 -0.504347 1.57079 -0.0741 -0</pose>
        <inertial>
          <pose frame=''>0 0 0 0 -0 0</pose>
          <mass>0.304193</mass>
          <inertia>
            <ixx>0.00138454</ixx>
            <ixy>7.30922e-05</ixy>
            <ixz>1.85038e-06</ixz>
            <iyy>0.000363767</iyy>
            <iyz>0.000114747</iyz>
            <izz>0.0011366</izz>
          </inertia>
        </inertial>
        <collision name='corner_rf_collision_collision'>
          <pose frame=''>0.44631 0.10755 -0.09331 0 -0 0</pose>
          <geometry>
            <mesh>
              <scale>1 1 1</scale>
              <uri>/home/ashwin/rover_ws/src/2020_rover/rover_sim/models/rover/meshes/corner_rf.STL</uri>
            </mesh>
          </geometry>
          <surface>
            <contact>
              <ode/>
            </contact>
            <friction>
              <ode/>
              <torsional>
                <ode/>
              </torsional>
            </friction>
            <bounce/>
          </surface>
          <max_contacts>10</max_contacts>
        </collision>
        <visual name='corner_rf_visual_visual'>
          <pose frame=''>0.44631 0.10755 -0.09331 0 -0 0</pose>
          <geometry>
            <mesh>
              <scale>1 1 1</scale>
              <uri>/home/ashwin/rover_ws/src/2020_rover/rover_sim/models/rover/meshes/corner_rf.dae</uri>
            </mesh>
          </geometry>
          <material>
            <script>
              <uri>__default__</uri>
              <name>__default__</name>
            </script>
          </material>
        </visual>
        <velocity_decay/>
        <sensor name='corner_rf_contact_sensor' type='contact'>
          <update_rate>30</update_rate>
          <always_on>1</always_on>
          <contact>
            <collision>corner_rf_collision_collision</collision>
            <topic>rover/bumper_contact</topic>
          </contact>
          <plugin name='gazebo_ros_bumper_controller' filename='libgazebo_ros_bumper.so'>
            <alwaysOn>1</alwaysOn>
            <updateRate>3.0</updateRate>
            <bumperTopicName>rover/robot_bumper</bumperTopicName>
            <frameName>corner_rf</frameName>
            <robotNamespace>/</robotNamespace>
          </plugin>
        </sensor>
        <gravity>1</gravity>
        <velocity_decay/>
        <sensor name='imu' type='imu'>
          <always_on>1</always_on>
          <pose frame=''>0 -0.1 0 -1.58 0 0</pose>
          <imu/>
        </sensor>
        <self_collide>0</self_collide>
        <enable_wind>0</enable_wind>
        <kinematic>0</kinematic>
      </link>
      <joint name='bogie_right_corner_rf' type='revolute'>
        <child>corner_rf</child>
        <parent>bogie_right</parent>
        <axis>
          <xyz>2e-06 -6e-06 -0.999994</xyz>
          <limit>
            <lower>-1e+16</lower>
            <upper>1e+16</upper>
          </limit>
          <dynamics>
            <spring_reference>0</spring_reference>
            <spring_stiffness>0</spring_stiffness>
          </dynamics>
          <use_parent_model_frame>1</use_parent_model_frame>
        </axis>
      </joint>
      <link name='wheel_rf'>
        <pose frame=''>-0.364276 0.175448 -0.604589 1.57079 -0.0741 -0</pose>
        <inertial>
          <pose frame=''>0 0 0 0 -0 0</pose>
          <mass>1.36815</mass>
          <inertia>
            <ixx>0.00366886</ixx>
            <ixy>6.90349e-08</ixy>
            <ixz>4.68184e-05</ixz>
            <iyy>0.00366752</iyy>
            <iyz>3.44458e-06</iyz>
            <izz>0.00544645</izz>
          </inertia>
        </inertial>
        <collision name='wheel_rf_collision_collision'>
          <pose frame=''>0.44223 0.20838 -0.08295 0 -0 0</pose>
          <geometry>
            <mesh>
              <scale>1 1 1</scale>
              <uri>/home/ashwin/rover_ws/src/2020_rover/rover_sim/models/rover/meshes/wheel_rf.STL</uri>
            </mesh>
          </geometry>
          <max_contacts>10</max_contacts>
          <surface>
            <contact>
              <ode/>
            </contact>
            <bounce/>
            <friction>
              <torsional>
                <ode/>
              </torsional>
              <ode/>
            </friction>
          </surface>
        </collision>
        <visual name='wheel_rf_visual_visual'>
          <pose frame=''>0.44223 0.20838 -0.08295 0 -0 0</pose>
          <geometry>
            <mesh>
              <scale>1 1 1</scale>
              <uri>/home/ashwin/rover_ws/src/2020_rover/rover_sim/models/rover/meshes/wheel_rf.dae</uri>
            </mesh>
          </geometry>
        </visual>
        <self_collide>0</self_collide>
        <enable_wind>0</enable_wind>
        <kinematic>0</kinematic>
      </link>
      <joint name='corner_rf_wheel_rf' type='revolute'>
        <child>wheel_rf</child>
        <parent>corner_rf</parent>
        <axis>
          <xyz>-0.026382 0.99965 -9e-06</xyz>
          <limit>
            <lower>-1e+16</lower>
            <upper>1e+16</upper>
          </limit>
          <dynamics>
            <spring_reference>0</spring_reference>
            <spring_stiffness>0</spring_stiffness>
          </dynamics>
          <use_parent_model_frame>1</use_parent_model_frame>
        </axis>
      </joint>
      <link name='wheel_rm'>
        <pose frame=''>-0.108944 0.251588 -0.585023 1.57079 -0.0741 -0</pose>
        <inertial>
          <pose frame=''>0 0 0 0 -0 0</pose>
          <mass>1.36815</mass>
          <inertia>
            <ixx>0.00366762</ixx>
            <ixy>3.57127e-08</ixy>
            <ixz>1.58692e-08</ixz>
            <iyy>0.00366752</iyy>
            <iyz>2.77979e-08</iyz>
            <izz>0.00544769</izz>
          </inertia>
        </inertial>
        <collision name='wheel_rm_collision_collision'>
          <pose frame=''>0.18614 0.20777 -0.0068 0 -0 0</pose>
          <geometry>
            <mesh>
              <scale>1 1 1</scale>
              <uri>/home/ashwin/rover_ws/src/2020_rover/rover_sim/models/rover/meshes/wheel_rm.STL</uri>
            </mesh>
          </geometry>
          <max_contacts>10</max_contacts>
          <surface>
            <contact>
              <ode/>
            </contact>
            <bounce/>
            <friction>
              <torsional>
                <ode/>
              </torsional>
              <ode/>
            </friction>
          </surface>
        </collision>
        <visual name='wheel_rm_visual_visual'>
          <pose frame=''>0.18614 0.20777 -0.0068 0 -0 0</pose>
          <geometry>
            <mesh>
              <scale>1 1 1</scale>
              <uri>/home/ashwin/rover_ws/src/2020_rover/rover_sim/models/rover/meshes/wheel_rm.dae</uri>
            </mesh>
          </geometry>
        </visual>
        <self_collide>0</self_collide>
        <enable_wind>0</enable_wind>
        <kinematic>0</kinematic>
      </link>
      <joint name='bogie_right_wheel_rm' type='revolute'>
        <child>wheel_rm</child>
        <parent>bogie_right</parent>
        <axis>
          <xyz>0 1 -6e-06</xyz>
          <limit>
            <lower>-1e+16</lower>
            <upper>1e+16</upper>
          </limit>
          <dynamics>
            <spring_reference>0</spring_reference>
            <spring_stiffness>0</spring_stiffness>
          </dynamics>
          <use_parent_model_frame>1</use_parent_model_frame>
        </axis>
      </joint>
      <link name='corner_rb'>
        <pose frame=''>0.183639 0.165089 -0.467099 1.57079 -0.0741 -0</pose>
        <inertial>
          <pose frame=''>0 0 0 0 -0 0</pose>
          <mass>0.304193</mass>
          <inertia>
            <ixx>0.00137605</ixx>
            <ixy>0.000117918</ixy>
            <ixz>6.30849e-06</ixz>
            <iyy>0.000372224</iyy>
            <iyz>0.00011462</iyz>
            <izz>0.00113663</izz>
          </inertia>
        </inertial>
        <collision name='corner_rb_collision_collision'>
          <pose frame=''>-0.11436 0.11182 -0.09331 0 -0 0</pose>
          <geometry>
            <mesh>
              <scale>1 1 1</scale>
              <uri>/home/ashwin/rover_ws/src/2020_rover/rover_sim/models/rover/meshes/corner_rb.STL</uri>
            </mesh>
          </geometry>
          <surface>
            <contact>
              <ode/>
            </contact>
            <friction>
              <ode/>
              <torsional>
                <ode/>
              </torsional>
            </friction>
            <bounce/>
          </surface>
          <max_contacts>10</max_contacts>
        </collision>
        <visual name='corner_rb_visual_visual'>
          <pose frame=''>-0.11436 0.11182 -0.09331 0 -0 0</pose>
          <geometry>
            <mesh>
              <scale>1 1 1</scale>
              <uri>/home/ashwin/rover_ws/src/2020_rover/rover_sim/models/rover/meshes/corner_rb.dae</uri>
            </mesh>
          </geometry>
          <material>
            <script>
              <uri>__default__</uri>
              <name>__default__</name>
            </script>
          </material>
        </visual>
        <velocity_decay/>
        <sensor name='corner_rb_contact_sensor' type='contact'>
          <update_rate>30</update_rate>
          <always_on>1</always_on>
          <contact>
            <collision>corner_rb_collision_collision</collision>
            <topic>rover/bumper_contact</topic>
          </contact>
          <plugin name='gazebo_ros_bumper_controller' filename='libgazebo_ros_bumper.so'>
            <alwaysOn>1</alwaysOn>
            <updateRate>3.0</updateRate>
            <bumperTopicName>rover/robot_bumper</bumperTopicName>
            <frameName>corner_rb</frameName>
            <robotNamespace>/</robotNamespace>
          </plugin>
        </sensor>
        <gravity>1</gravity>
        <velocity_decay/>
        <sensor name='imu' type='imu'>
          <always_on>1</always_on>
          <pose frame=''>0 -0.1 0 -1.58 0 0</pose>
          <imu/>
        </sensor>
        <self_collide>0</self_collide>
        <enable_wind>0</enable_wind>
        <kinematic>0</kinematic>
      </link>
      <joint name='rocker_right_corner_rb' type='revolute'>
        <child>corner_rb</child>
        <parent>rocker_right</parent>
        <axis>
          <xyz>-0.044523 -6e-06 -0.999008</xyz>
          <limit>
            <lower>-1e+16</lower>
            <upper>1e+16</upper>
          </limit>
          <dynamics>
            <spring_reference>0</spring_reference>
            <spring_stiffness>0</spring_stiffness>
          </dynamics>
          <use_parent_model_frame>1</use_parent_model_frame>
        </axis>
      </joint>
      <link name='wheel_rb'>
        <pose frame=''>0.198558 0.175698 -0.565404 1.57079 -0.0741 -0</pose>
        <inertial>
          <pose frame=''>0 0 0 0 -0 0</pose>
          <mass>1.36815</mass>
          <inertia>
            <ixx>0.00366909</ixx>
            <ixy>1.39874e-07</ixy>
            <ixz>5.11667e-05</ixz>
            <iyy>0.00366754</iyy>
            <iyz>6.06942e-06</iyz>
            <izz>0.00544619</izz>
          </inertia>
        </inertial>
        <collision name='wheel_rb_collision_collision'>
          <pose frame=''>-0.12196 0.21097 -0.08269 0 -0 0</pose>
          <geometry>
            <mesh>
              <scale>1 1 1</scale>
              <uri>/home/ashwin/rover_ws/src/2020_rover/rover_sim/models/rover/meshes/wheel_rb.STL</uri>
            </mesh>
          </geometry>
          <max_contacts>10</max_contacts>
          <surface>
            <contact>
              <ode/>
            </contact>
            <bounce/>
            <friction>
              <torsional>
                <ode/>
              </torsional>
              <ode/>
            </friction>
          </surface>
        </collision>
        <visual name='wheel_rb_visual_visual'>
          <pose frame=''>-0.12196 0.21097 -0.08269 0 -0 0</pose>
          <geometry>
            <mesh>
              <scale>1 1 1</scale>
              <uri>/home/ashwin/rover_ws/src/2020_rover/rover_sim/models/rover/meshes/wheel_rb.dae</uri>
            </mesh>
          </geometry>
        </visual>
        <self_collide>0</self_collide>
        <enable_wind>0</enable_wind>
        <kinematic>0</kinematic>
      </link>
      <joint name='corner_rb_wheel_rb' type='revolute'>
        <child>wheel_rb</child>
        <parent>corner_rb</parent>
        <axis>
          <xyz>-0.028924 0.99958 0.001276</xyz>
          <limit>
            <lower>-1e+16</lower>
            <upper>1e+16</upper>
          </limit>
          <dynamics>
            <spring_reference>0</spring_reference>
            <spring_stiffness>0</spring_stiffness>
          </dynamics>
          <use_parent_model_frame>1</use_parent_model_frame>
        </axis>
      </joint>
      <plugin name='gazebo_ros_control' filename='libgazebo_ros_control.so'>
        <robotNamespace>rover</robotNamespace>
        <robotSimType>gazebo_ros_control/DefaultRobotHWSim</robotSimType>
        <legacyModeNS>1</legacyModeNS>
        <odometryTopic>rover/odom</odometryTopic>
        <odometryFrame>odom</odometryFrame>
        <odometrySource>world</odometrySource>
        <publishOdomTF>1</publishOdomTF>
      </plugin>
      <plugin name='robot_groundtruth_sim' filename='libgazebo_ros_p3d.so'>
        <alwaysOn>1</alwaysOn>
        <updateRate>100.0</updateRate>
        <bodyName>body</bodyName>
        <topicName>rover/odom</topicName>
        <frameName>world</frameName>
        <robotNamespace>/</robotNamespace>
      </plugin>
      <plugin name='imu_plugin' filename='libgazebo_ros_imu.so'>
        <alwaysOn>1</alwaysOn>
        <bodyName>body</bodyName>
        <topicName>rover/imu</topicName>
        <serviceName>rover/imu_service</serviceName>
        <gaussianNoise>0</gaussianNoise>
        <updateRate>30</updateRate>
        <imu>
          <noise>
            <type>gaussian</type>
            <rate>
              <mean>0.0</mean>
              <stddev>2e-4</stddev>
              <bias_mean>0.0000075</bias_mean>
              <bias_stddev>0.0000008</bias_stddev>
            </rate>
            <accel>
              <mean>0.0</mean>
              <stddev>1.7e-2</stddev>
              <bias_mean>0.1</bias_mean>
              <bias_stddev>0.001</bias_stddev>
            </accel>
          </noise>
        </imu>
        <robotNamespace>/</robotNamespace>
        <frameName>body</frameName>
        <xyzOffset>0.032 0 -0.068</xyzOffset>
        <rpyOffset>0 0 -3.14</rpyOffset>
      </plugin>
      <plugin name='imu_plugin' filename='libgazebo_ros_imu.so'>
        <alwaysOn>1</alwaysOn>
        <bodyName>corner_lb</bodyName>
        <topicName>rover/imu/wheel_lb</topicName>
        <serviceName>rover/imu_wheel_lb_service</serviceName>
        <gaussianNoise>0</gaussianNoise>
        <updateRate>30</updateRate>
        <imu>
          <noise>
            <type>gaussian</type>
            <rate>
              <mean>0.0</mean>
              <stddev>2e-4</stddev>
              <bias_mean>0.0000075</bias_mean>
              <bias_stddev>0.0000008</bias_stddev>
            </rate>
            <accel>
              <mean>0.0</mean>
              <stddev>1.7e-2</stddev>
              <bias_mean>0.1</bias_mean>
              <bias_stddev>0.001</bias_stddev>
            </accel>
          </noise>
        </imu>
        <robotNamespace>/</robotNamespace>
        <frameName>corner_lb</frameName>
        <xyzOffset>-0.04 0.069 -0.005</xyzOffset>
        <rpyOffset>1.58 -0 0</rpyOffset>
      </plugin>
      <plugin name='imu_plugin' filename='libgazebo_ros_imu.so'>
        <alwaysOn>1</alwaysOn>
        <bodyName>corner_rb</bodyName>
        <topicName>rover/imu/wheel_rb</topicName>
        <serviceName>rover/imu_wheel_rb_service</serviceName>
        <gaussianNoise>0</gaussianNoise>
        <updateRate>30</updateRate>
        <imu>
          <noise>
            <type>gaussian</type>
            <rate>
              <mean>0.0</mean>
              <stddev>2e-4</stddev>
              <bias_mean>0.0000075</bias_mean>
              <bias_stddev>0.0000008</bias_stddev>
            </rate>
            <accel>
              <mean>0.0</mean>
              <stddev>1.7e-2</stddev>
              <bias_mean>0.1</bias_mean>
              <bias_stddev>0.001</bias_stddev>
            </accel>
          </noise>
        </imu>
        <robotNamespace>/</robotNamespace>
        <frameName>corner_rb</frameName>
        <xyzOffset>0 0.1 0</xyzOffset>
        <rpyOffset>1.58 -0 0</rpyOffset>
      </plugin>
      <plugin name='imu_plugin' filename='libgazebo_ros_imu.so'>
        <alwaysOn>1</alwaysOn>
        <bodyName>corner_lf</bodyName>
        <topicName>rover/imu/wheel_lf</topicName>
        <serviceName>rover/imu_wheel_lf_service</serviceName>
        <gaussianNoise>0</gaussianNoise>
        <updateRate>30</updateRate>
        <imu>
          <noise>
            <type>gaussian</type>
            <rate>
              <mean>0.0</mean>
              <stddev>2e-4</stddev>
              <bias_mean>0.0000075</bias_mean>
              <bias_stddev>0.0000008</bias_stddev>
            </rate>
            <accel>
              <mean>0.0</mean>
              <stddev>1.7e-2</stddev>
              <bias_mean>0.1</bias_mean>
              <bias_stddev>0.001</bias_stddev>
            </accel>
          </noise>
        </imu>
        <robotNamespace>/</robotNamespace>
        <frameName>corner_lf</frameName>
        <xyzOffset>-0.028 0.089 -0.01</xyzOffset>
        <rpyOffset>1.58 -0 0</rpyOffset>
      </plugin>
      <plugin name='imu_plugin' filename='libgazebo_ros_imu.so'>
        <alwaysOn>1</alwaysOn>
        <bodyName>corner_rf</bodyName>
        <topicName>rover/imu/wheel_rf</topicName>
        <serviceName>rover/imu_wheel_rf_service</serviceName>
        <gaussianNoise>0</gaussianNoise>
        <updateRate>30</updateRate>
        <imu>
          <noise>
            <type>gaussian</type>
            <rate>
              <mean>0.0</mean>
              <stddev>2e-4</stddev>
              <bias_mean>0.0000075</bias_mean>
              <bias_stddev>0.0000008</bias_stddev>
            </rate>
            <accel>
              <mean>0.0</mean>
              <stddev>1.7e-2</stddev>
              <bias_mean>0.1</bias_mean>
              <bias_stddev>0.001</bias_stddev>
            </accel>
          </noise>
        </imu>
        <robotNamespace>/</robotNamespace>
        <frameName>corner_rf</frameName>
        <xyzOffset>0 0.1 0</xyzOffset>
        <rpyOffset>1.58 -0 0</rpyOffset>
      </plugin>
      <plugin name='imu_plugin' filename='libgazebo_ros_imu.so'>
        <alwaysOn>1</alwaysOn>
        <bodyName>bogie_left</bodyName>
        <topicName>rover/imu/wheel_lm</topicName>
        <serviceName>rover/imu_wheel_lm_service</serviceName>
        <gaussianNoise>0</gaussianNoise>
        <updateRate>30</updateRate>
        <imu>
          <noise>
            <type>gaussian</type>
            <rate>
              <mean>0.0</mean>
              <stddev>2e-4</stddev>
              <bias_mean>0.0000075</bias_mean>
              <bias_stddev>0.0000008</bias_stddev>
            </rate>
            <accel>
              <mean>0.0</mean>
              <stddev>1.7e-2</stddev>
              <bias_mean>0.1</bias_mean>
              <bias_stddev>0.001</bias_stddev>
            </accel>
          </noise>
        </imu>
        <robotNamespace>/</robotNamespace>
        <frameName>bogie_left</frameName>
        <xyzOffset>-0.105 0.179 -0.078</xyzOffset>
        <rpyOffset>1.58 -0 0</rpyOffset>
      </plugin>
      <static>0</static>
      <plugin name='imu_plugin' filename='libgazebo_ros_imu.so'>
        <alwaysOn>1</alwaysOn>
        <bodyName>bogie_right</bodyName>
        <topicName>rover/imu/wheel_rm</topicName>
        <serviceName>rover/imu_wheel_rm_service</serviceName>
        <gaussianNoise>0</gaussianNoise>
        <updateRate>30</updateRate>
        <imu>
          <noise>
            <type>gaussian</type>
            <rate>
              <mean>0.0</mean>
              <stddev>2e-4</stddev>
              <bias_mean>0.0000075</bias_mean>
              <bias_stddev>0.0000008</bias_stddev>
            </rate>
            <accel>
              <mean>0.0</mean>
              <stddev>1.7e-2</stddev>
              <bias_mean>0.1</bias_mean>
              <bias_stddev>0.001</bias_stddev>
            </accel>
          </noise>
        </imu>
        <robotNamespace>/</robotNamespace>
        <frameName>bogie_right</frameName>
        <xyzOffset>-0.066 0.182 0.079</xyzOffset>
        <rpyOffset>1.58 -0 0</rpyOffset>
      </plugin>
      <pose frame=''>0 0 -0.033356 0.031965 0.091685 0.003569</pose>
    </model>
    <model name='aruco_visual_marker_0_pad'>
      <link name='aruco_visual_marker_0::marker'>
        <pose frame=''>0 0 0 0 -0 0</pose>
        <visual name='visual'>
          <geometry>
            <box>
              <size>0.1778 0.1778 0.001</size>
            </box>
          </geometry>
          <material>
            <script>
              <uri>model://aruco_visual_marker_0/materials/scripts</uri>
              <uri>model://aruco_visual_marker_0/materials/textures</uri>
              <name>ArucoVisualMarker0/Marker</name>
            </script>
            <ambient>1 1 1 1</ambient>
            <diffuse>1 1 1 1</diffuse>
            <specular>0 0 0 1</specular>
            <emissive>1 1 1 0</emissive>
            <shader type='vertex'>
              <normal_map>__default__</normal_map>
            </shader>
          </material>
          <pose frame=''>0 0 0 0 -0 0</pose>
          <cast_shadows>1</cast_shadows>
          <transparency>0</transparency>
        </visual>
        <collision name='collision'>
          <laser_retro>0</laser_retro>
          <max_contacts>10</max_contacts>
          <pose frame=''>0 0 0 0 -0 0</pose>
          <geometry>
            <box>
              <size>0.1778 0.1778 0.001</size>
            </box>
          </geometry>
          <surface>
            <contact>
              <ode/>
            </contact>
            <bounce/>
            <friction>
              <torsional>
                <ode/>
              </torsional>
              <ode/>
            </friction>
          </surface>
        </collision>
        <self_collide>0</self_collide>
        <enable_wind>0</enable_wind>
        <kinematic>0</kinematic>
      </link>
      <static>1</static>
      <allow_auto_disable>1</allow_auto_disable>
      <link name='marker_pad_large'>
        <pose frame='aruco_visual_marker_0::marker'>-0.035 0 -1e-05 0 -0 0</pose>
        <visual name='visual'>
          <geometry>
            <box>
              <size>0.297 0.21 0.001</size>
            </box>
          </geometry>
          <material>
            <lighting>1</lighting>
            <script>
              <uri>file://media/materials/scripts/gazebo.material</uri>
              <name>Gazebo/White</name>
            </script>
            <ambient>0.3 0.3 0.3 1</ambient>
            <diffuse>0.7 0.7 0.7 1</diffuse>
            <specular>0.01 0.01 0.01 1</specular>
            <emissive>1 1 1 0</emissive>
            <shader type='vertex'>
              <normal_map>__default__</normal_map>
            </shader>
          </material>
          <cast_shadows>1</cast_shadows>
          <transparency>0</transparency>
        </visual>
        <collision name='collision'>
          <laser_retro>0</laser_retro>
          <max_contacts>10</max_contacts>
          <pose frame=''>0 0 0 0 -0 0</pose>
          <geometry>
            <box>
              <size>0.297 0.21 0.001</size>
            </box>
          </geometry>
          <surface>
            <friction>
              <ode>
                <mu>1</mu>
                <mu2>1</mu2>
                <fdir1>0 0 0</fdir1>
                <slip1>0</slip1>
                <slip2>0</slip2>
              </ode>
              <torsional>
                <coefficient>1</coefficient>
                <patch_radius>0</patch_radius>
                <surface_radius>0</surface_radius>
                <use_patch_radius>1</use_patch_radius>
                <ode>
                  <slip>0</slip>
                </ode>
              </torsional>
            </friction>
            <bounce>
              <restitution_coefficient>0</restitution_coefficient>
              <threshold>1e+06</threshold>
            </bounce>
            <contact>
              <collide_without_contact>0</collide_without_contact>
              <collide_without_contact_bitmask>1</collide_without_contact_bitmask>
              <collide_bitmask>1</collide_bitmask>
              <ode>
                <soft_cfm>0</soft_cfm>
                <soft_erp>0.2</soft_erp>
                <kp>1e+13</kp>
                <kd>1</kd>
                <max_vel>0.01</max_vel>
                <min_depth>0</min_depth>
              </ode>
              <bullet>
                <split_impulse>1</split_impulse>
                <split_impulse_penetration_threshold>-0.01</split_impulse_penetration_threshold>
                <soft_cfm>0</soft_cfm>
                <soft_erp>0.2</soft_erp>
                <kp>1e+13</kp>
                <kd>1</kd>
              </bullet>
            </contact>
          </surface>
        </collision>
        <self_collide>0</self_collide>
        <enable_wind>0</enable_wind>
        <kinematic>0</kinematic>
      </link>
      <link name='marker_num'>
        <pose frame='marker_pad_large'>-0.14 0 1e-05 0 -0 0</pose>
        <visual name='visual'>
          <geometry>
            <box>
              <size>0.05 0.05 0.001</size>
            </box>
          </geometry>
          <material>
            <script>
              <uri>model://aruco_visual_marker_0_pad/materials/scripts</uri>
              <uri>model://aruco_visual_marker_0_pad/materials/textures</uri>
              <name>ArucoVisualMarker0/Num</name>
            </script>
            <ambient>1 1 1 1</ambient>
            <diffuse>1 1 1 1</diffuse>
            <specular>0 0 0 1</specular>
            <emissive>1 1 1 0</emissive>
            <shader type='vertex'>
              <normal_map>__default__</normal_map>
            </shader>
          </material>
          <pose frame=''>0 0 0 0 -0 0</pose>
          <cast_shadows>1</cast_shadows>
          <transparency>0</transparency>
        </visual>
        <collision name='collision'>
          <laser_retro>0</laser_retro>
          <max_contacts>10</max_contacts>
          <pose frame=''>0 0 0 0 -0 0</pose>
          <geometry>
            <box>
              <size>0.05 0.05 0.001</size>
            </box>
          </geometry>
          <surface>
            <friction>
              <ode>
                <mu>1</mu>
                <mu2>1</mu2>
                <fdir1>0 0 0</fdir1>
                <slip1>0</slip1>
                <slip2>0</slip2>
              </ode>
              <torsional>
                <coefficient>1</coefficient>
                <patch_radius>0</patch_radius>
                <surface_radius>0</surface_radius>
                <use_patch_radius>1</use_patch_radius>
                <ode>
                  <slip>0</slip>
                </ode>
              </torsional>
            </friction>
            <bounce>
              <restitution_coefficient>0</restitution_coefficient>
              <threshold>1e+06</threshold>
            </bounce>
            <contact>
              <collide_without_contact>0</collide_without_contact>
              <collide_without_contact_bitmask>1</collide_without_contact_bitmask>
              <collide_bitmask>1</collide_bitmask>
              <ode>
                <soft_cfm>0</soft_cfm>
                <soft_erp>0.2</soft_erp>
                <kp>1e+13</kp>
                <kd>1</kd>
                <max_vel>0.01</max_vel>
                <min_depth>0</min_depth>
              </ode>
              <bullet>
                <split_impulse>1</split_impulse>
                <split_impulse_penetration_threshold>-0.01</split_impulse_penetration_threshold>
                <soft_cfm>0</soft_cfm>
                <soft_erp>0.2</soft_erp>
                <kp>1e+13</kp>
                <kd>1</kd>
              </bullet>
            </contact>
          </surface>
        </collision>
        <self_collide>0</self_collide>
        <enable_wind>0</enable_wind>
        <kinematic>0</kinematic>
      </link>
      <joint name='marker_JOINT_marker_pad_large' type='revolute'>
        <parent>aruco_visual_marker_0::marker</parent>
        <child>marker_pad_large</child>
        <axis>
          <xyz>0 0 1</xyz>
          <limit>
            <upper>0</upper>
            <lower>0</lower>
          </limit>
          <use_parent_model_frame>0</use_parent_model_frame>
          <dynamics>
            <spring_reference>0</spring_reference>
            <spring_stiffness>0</spring_stiffness>
          </dynamics>
        </axis>
      </joint>
      <joint name='pad_large_JOINT_marker_num' type='revolute'>
        <parent>marker_pad_large</parent>
        <child>marker_num</child>
        <axis>
          <xyz>0 0 1</xyz>
          <limit>
            <upper>0</upper>
            <lower>0</lower>
          </limit>
          <use_parent_model_frame>0</use_parent_model_frame>
          <dynamics>
            <spring_reference>0</spring_reference>
            <spring_stiffness>0</spring_stiffness>
          </dynamics>
        </axis>
      </joint>
      <static>1</static>
      <allow_auto_disable>1</allow_auto_disable>
      <pose frame=''>-0.686723 -0.010974 0 0 -0 0</pose>
    </model>
    <model name='flag'>
      <static>1</static>
      <link name='link'>
        <collision name='collision'>
          <geometry>
            <mesh>
              <uri>model://flag/meshes/flag.dae</uri>
              <scale>1 1 1</scale>
            </mesh>
          </geometry>
          <surface>
            <contact>
              <collide_bitmask>65535</collide_bitmask>
              <ode/>
            </contact>
            <friction>
              <ode>
                <mu>100</mu>
                <mu2>50</mu2>
              </ode>
              <torsional>
                <ode/>
              </torsional>
            </friction>
            <bounce/>
          </surface>
          <max_contacts>10</max_contacts>
        </collision>
        <visual name='visual'>
          <geometry>
            <mesh>
              <uri>model://flag/meshes/flag.dae</uri>
              <scale>1 1 1</scale>
            </mesh>
          </geometry>
        </visual>
        <self_collide>0</self_collide>
        <enable_wind>0</enable_wind>
        <kinematic>0</kinematic>
      </link>
      <pose frame=''>-20.0951 15.348 0 0 -0 0</pose>
    </model>
    <model name='takeoff_zone'>
      <static>1</static>
      <link name='link'>
        <collision name='collision'>
          <geometry>
            <mesh>
              <uri>model://takeoff_zone/meshes/takeoff_zone.dae</uri>
              <scale>1 1 1</scale>
            </mesh>
          </geometry>
          <surface>
            <contact>
              <collide_bitmask>65535</collide_bitmask>
              <ode/>
            </contact>
            <friction>
              <ode>
                <mu>100</mu>
                <mu2>50</mu2>
              </ode>
              <torsional>
                <ode/>
              </torsional>
            </friction>
            <bounce/>
          </surface>
          <max_contacts>10</max_contacts>
        </collision>
        <visual name='visual'>
          <geometry>
            <mesh>
              <uri>model://takeoff_zone/meshes/takeoff_zone.dae</uri>
              <scale>1 1 1</scale>
            </mesh>
          </geometry>
        </visual>
        <self_collide>0</self_collide>
        <enable_wind>0</enable_wind>
        <kinematic>0</kinematic>
      </link>
      <pose frame=''>-16.2446 19.8129 0 0 -0 0</pose>
    </model>
    <state world_name='default'>
      <sim_time>241 203000000</sim_time>
      <real_time>377 267495633</real_time>
      <wall_time>1592133573 479218090</wall_time>
      <iterations>13038</iterations>
      <model name='aruco_visual_marker_0_pad'>
        <pose frame=''>-24.1126 27.7301 0.219829 -2.44354 1.53475 -3.14159</pose>
        <scale>1 1 1</scale>
        <link name='aruco_visual_marker_0::marker'>
          <pose frame=''>-24.1126 27.7301 0.219829 -2.44354 1.53475 -3.14159</pose>
          <velocity>0 0 0 0 -0 0</velocity>
          <acceleration>0 0 0 0 -0 0</acceleration>
          <wrench>0 0 0 0 -0 0</wrench>
        </link>
        <link name='marker_num'>
          <pose frame=''>-24.1075 27.7301 0.359738 -2.44354 1.53475 -3.14159</pose>
          <velocity>0 0 0 0 -0 0</velocity>
          <acceleration>0 0 0 0 -0 0</acceleration>
          <wrench>0 0 0 0 -0 0</wrench>
        </link>
        <link name='marker_pad_large'>
          <pose frame=''>-24.1113 27.7301 0.254807 -2.44354 1.53475 -3.14159</pose>
          <velocity>0 0 0 0 -0 0</velocity>
          <acceleration>0 0 0 0 -0 0</acceleration>
          <wrench>0 0 0 0 -0 0</wrench>
        </link>
      </model>
      <model name='crater'>
        <pose frame=''>-48.502 1.5 -2.1 0 -0 0</pose>
        <scale>1 1 1</scale>
        <link name='link'>
          <pose frame=''>-48.502 1.5 -2.1 0 -0 0</pose>
          <velocity>0 0 0 0 -0 0</velocity>
          <acceleration>0 0 0 0 -0 0</acceleration>
          <wrench>0 0 0 0 -0 0</wrench>
        </link>
      </model>
      <model name='curiosity_path'>
        <pose frame=''>-133.601 131.008 14.21 0 -0 0</pose>
        <scale>1 1 1</scale>
        <link name='link'>
          <pose frame=''>-133.601 131.008 14.21 0 -0 0</pose>
          <velocity>0 0 0 0 -0 0</velocity>
          <acceleration>0 0 0 0 -0 0</acceleration>
          <wrench>0 0 0 0 -0 0</wrench>
        </link>
      </model>
      <model name='flag'>
        <pose frame=''>-20.0962 15.331 -0.815546 0 -0 0</pose>
        <scale>1 1 1</scale>
        <link name='link'>
          <pose frame=''>-20.0962 15.331 -0.815546 0 -0 0</pose>
          <velocity>0 0 0 0 -0 0</velocity>
          <acceleration>0 0 0 0 -0 0</acceleration>
          <wrench>0 0 0 0 -0 0</wrench>
        </link>
      </model>
      <model name='rover'>
        <pose frame=''>-1.46113 0.211238 -0.0547 0.042773 0.14393 0.051602</pose>
        <scale>1 1 1</scale>
        <link name='body'>
          <pose frame=''>-1.46113 0.211238 -0.0547 0.042773 0.14393 0.051602</pose>
          <velocity>-0.008584 0.023353 -0.045854 -0.048557 -0.05275 0.103216</velocity>
          <acceleration>-0.041207 0.532999 -2.84383 0.212122 0.403264 -2.02125</acceleration>
          <wrench>-0.119586 1.54682 -8.2531 0 -0 0</wrench>
        </link>
        <link name='bogie_left'>
          <pose frame=''>-1.69772 0.039794 -0.44065 1.61582 -0.049701 0.066221</pose>
          <velocity>-0.004628 0.021878 0.008835 -0.178648 -0.010164 -0.070819</velocity>
          <acceleration>1.03325 0.84096 1.22938 0.031402 -0.331747 1.74715</acceleration>
          <wrench>0.641914 0.522455 0.763766 0 -0 0</wrench>
        </link>
        <link name='bogie_right'>
          <pose frame=''>-1.70772 0.39028 -0.441865 1.62304 0.012067 0.043808</pose>
          <velocity>-0.006651 -0.014628 -0.058467 0.037891 -0.084277 0.09005</velocity>
          <acceleration>-0.312444 -1.78943 -3.94448 -0.854899 0.720755 0.167298</acceleration>
          <wrench>-0.194109 -1.1117 -2.45055 0 -0 0</wrench>
        </link>
        <link name='corner_lb'>
          <pose frame=''>-1.34063 0.07599 -0.547941 1.58923 0.062759 -0.114823</pose>
          <velocity>0.029023 -0.034636 -0.08631 0.064976 0.417045 1.30442</velocity>
          <acceleration>1.68796 -3.78472 -4.89152 2.63318 1.19293 -1.03296</acceleration>
          <wrench>0.513464 -1.15128 -1.48797 0 -0 0</wrench>
        </link>
        <link name='corner_lf'>
          <pose frame=''>-1.88757 0.039372 -0.531289 1.6132 -0.052266 0.063986</pose>
          <velocity>-0.005531 0.04694 0.011731 -0.294476 0.003153 -0.84709</velocity>
          <acceleration>0.185552 3.3902 3.45269 -1.19198 1.16724 0.515673</acceleration>
          <wrench>0.056444 1.03128 1.05028 0 -0 0</wrench>
        </link>
        <link name='corner_rb'>
          <pose frame=''>-1.33931 0.402021 -0.520925 1.6318 -0.029114 0.222244</pose>
          <velocity>-0.007407 0.016383 -0.052551 -0.190447 0.052343 -1.66975</velocity>
          <acceleration>-0.21448 0.3064 -3.34045 -0.717596 0.533439 0.077847</acceleration>
          <wrench>-0.065243 0.093205 -1.01614 0 -0 0</wrench>
        </link>
        <link name='corner_rf'>
          <pose frame=''>-1.90213 0.377699 -0.521616 1.62327 0.012704 0.032608</pose>
          <velocity>0.001686 -0.028808 -0.074904 0.207095 -0.182985 1.99005</velocity>
          <acceleration>0.144815 -2.69756 -4.73362 3.04177 -1.06504 -2.84362</acceleration>
          <wrench>0.044052 -0.82058 -1.43993 0 -0 0</wrench>
        </link>
        <link name='rocker_left'>
          <pose frame=''>-1.49857 0.057607 -0.367086 1.63232 -0.043778 1.63719</pose>
          <velocity>0.025911 0.003649 -0.044682 -0.115005 0.227329 -0.132398</velocity>
          <acceleration>2.35199 -0.819544 -2.51031 1.36095 0.196097 2.19361</acceleration>
          <wrench>1.26495 -0.440769 -1.3501 0 -0 0</wrench>
        </link>
        <link name='rocker_right'>
          <pose frame=''>-1.51359 0.386763 -0.353223 1.61077 -0.019838 0.04468</pose>
          <velocity>-0.009689 0.004183 -0.056299 -0.066347 -0.02022 0.10334</velocity>
          <acceleration>-0.469881 -0.881043 -3.59655 -0.31396 -1.31967 -1.36852</acceleration>
          <wrench>-0.24727 -0.463639 -1.89264 0 -0 0</wrench>
        </link>
        <link name='wheel_lb'>
          <pose frame=''>-1.30538 0.068027 -0.6191 1.58506 0.234091 -0.112469</pose>
          <velocity>0.014641 0.016524 -0.100591 0.034852 -0.061746 1.27842</velocity>
          <acceleration>1.37599 0.679103 -5.64112 -2.24517 0.64304 0.515887</acceleration>
          <wrench>1.88256 0.929115 -7.7179 0 -0 0</wrench>
        </link>
        <link name='wheel_lf'>
          <pose frame=''>-1.85479 0.035417 -0.619519 1.61362 0.30627 0.079219</pose>
          <velocity>-0.005395 0.007678 0.011633 -0.127199 -0.10723 -0.834014</velocity>
          <acceleration>-1.10607 -0.542831 3.05791 2.95283 -0.959362 1.41256</acceleration>
          <wrench>-1.51326 -0.742675 4.18368 0 -0 0</wrench>
        </link>
        <link name='wheel_lm'>
          <pose frame=''>-1.58019 -0.022173 -0.618104 -1.63569 -0.704611 -3.03383</pose>
          <velocity>-0.013919 -0.003076 0.008055 0.049741 -0.196956 -0.197951</velocity>
          <acceleration>-1.22045 -0.570131 -0.220034 -1.68931 -1.33121 1.25438</acceleration>
          <wrench>-1.66975 -0.780019 -0.301037 0 -0 0</wrench>
        </link>
        <link name='wheel_rb'>
          <pose frame=''>-1.33281 0.420692 -0.618927 1.77568 -1.11973 0.051841</pose>
          <velocity>0.019984 -0.010737 -0.056127 -0.171641 0.085903 -1.68516</velocity>
          <acceleration>1.52404 -0.891855 -3.56106 -0.605918 0.491316 -0.480008</acceleration>
          <wrench>2.08511 -1.22019 -4.87206 0 -0 0</wrench>
        </link>
        <link name='wheel_rf'>
          <pose frame=''>-1.89983 0.39327 -0.621814 1.76142 -1.14806 -0.127978</pose>
          <velocity>-0.010669 -0.002132 -0.071239 0.206894 -0.092032 1.9914</velocity>
          <acceleration>-0.742075 -0.557485 -4.42243 0.419326 -0.613334 -1.44061</acceleration>
          <wrench>-1.01527 -0.762723 -6.05055 0 -0 0</wrench>
        </link>
        <link name='wheel_rm'>
          <pose frame=''>-1.64762 0.480512 -0.620533 -1.64143 -0.810384 -3.04477</pose>
          <velocity>3e-05 -0.003323 -0.050812 0.032268 0.011869 0.099339</velocity>
          <acceleration>-0.316034 -0.368529 -3.31191 1.08125 0.154212 2.1831</acceleration>
          <wrench>-0.432381 -0.504202 -4.53119 0 -0 0</wrench>
        </link>
      </model>
      <model name='takeoff_zone'>
        <pose frame=''>-24.1998 27.8583 -0.692887 0 -0 0</pose>
        <scale>1 1 1</scale>
        <link name='link'>
          <pose frame=''>-24.1998 27.8583 -0.692887 0 -0 0</pose>
          <velocity>0 0 0 0 -0 0</velocity>
          <acceleration>0 0 0 0 -0 0</acceleration>
          <wrench>0 0 0 0 -0 0</wrench>
        </link>
      </model>
      <light name='directional_light_1'>
        <pose frame=''>0 20 20 0.1 0.1 0</pose>
      </light>
      <light name='sun'>
        <pose frame=''>0 0 10 0 -0 0</pose>
      </light>
    </state>
    <gui fullscreen='0'>
      <camera name='user_camera'>
        <pose frame=''>-23.0111 25.9834 0.395297 0 0.323643 2.19221</pose>
        <view_controller>orbit</view_controller>
        <projection_type>perspective</projection_type>
      </camera>
    </gui>
  </world>
</sdf>
